Workbook

Sheet Bearing_Database
A1: FST 16 Wheel Bearing Catalog & Technical Database
A3: Part_Number | B3: Type | C3: Bore_d_mm | D3: OD_D_mm | E3: Width_B_mm | F3: Pitch_dm_mm | G3: Dynamic_Cr_kN | H3: Static_C0r_kN | I3: Contact_Angle_deg | J3: Ball_Diam_Dw_mm | K3: Ball_Count_Z | L3: Limiting_Speed_Grease_rpm | M3: Limiting_Speed_Oil_rpm | N3: Radial_Stiffness_Kr_kN_mm | O3: Axial_Stiffness_Ka_kN_mm | P3: Mass_g | Q3: Unit_Cost_EUR | R3: Lead_Time_Weeks | S3: Status
A4: Schaeffler 61816-Y | B4: Thin DGBB (Brass Cage) | C4: 80 | D4: 100 | E4: 10 | F4: 90 | G4: 13.8 | H4: 13.8 | I4: 0 | J4: 6 | K4: 28 | L4: 8000 | M4: 12300 | N4: 500 | O4: 7.353 | P4: 155 | Q4: 45 | R4: 1 | S4: Selected Baseline
A5: Schaeffler 61816-2RSR | B5: Thin DGBB (Rubber Sealed) | C5: 80 | D5: 100 | E5: 10 | F5: 90 | G5: 13.8 | H5: 13.8 | I5: 0 | J5: 6 | K5: 28 | L5: 3100 | M5: 3100 | N5: 500 | O5: 7.353 | P5: 160 | Q5: 50 | R5: 1 | S5: Rejected Seal Drag
A6: FAG B71816-C-TPA-P4S-UL | B6: Thin ACBB (15-deg Spindle) | C6: 80 | D6: 100 | E6: 10 | F6: 90 | G6: 14.6 | H6: 16.6 | I6: 15 | J6: 6.747 | K6: 35 | L6: 12000 | M6: 19000 | N6: 580 | O6: 75 | P6: 145 | Q6: 370 | R6: 18 | S6: Candidate 15-deg
A7: FAG B71816-E-TPA-P4S-UL | B7: Thin ACBB (25-deg Light) | C7: 80 | D7: 100 | E7: 10 | F7: 90 | G7: 13.7 | H7: 15.6 | I7: 25 | J7: 7.144 | K7: 35 | L7: 9500 | M7: 15000 | N7: 450 | O7: 121.4 | P7: 145 | Q7: 380 | R7: 18 | S7: Target Upgrade
A8: FAG B71816-E-TPA-P4S-UM | B8: Thin ACBB (25-deg Medium) | C8: 80 | D8: 100 | E8: 10 | F8: 90 | G8: 13.7 | H8: 15.6 | I8: 25 | J8: 7.144 | K8: 35 | L8: 9000 | M8: 14000 | N8: 520 | O8: 195.3 | P8: 145 | Q8: 410 | R8: 18 | S8: Candidate Medium
A9: FAG B71816-E-TPA-P4S-UH | B9: Thin ACBB (25-deg Heavy) | C9: 80 | D9: 100 | E9: 10 | F9: 90 | G9: 13.7 | H9: 15.6 | I9: 25 | J9: 7.144 | K9: 35 | L9: 8200 | M9: 13000 | N9: 590 | O9: 275.3 | P9: 145 | Q9: 440 | R9: 20 | S9: Candidate Heavy
A10: FAG HCB71816-E-TPA-P4S-UL | B10: Hybrid Ceramic ACBB (Si3N4) | C10: 80 | D10: 100 | E10: 10 | F10: 90 | G10: 9.5 | H10: 10.8 | I10: 25 | J10: 7.144 | K10: 35 | L10: 12000 | M10: 18000 | N10: 490 | O10: 135 | P10: 125 | Q10: 620 | R10: 24 | S10: Hybrid Ceramic
A11: FAG XCB71816-E-TPA-P4S-UL | B11: Cronidur 30 ACBB (F1 Grade) | C11: 80 | D11: 100 | E11: 10 | F11: 90 | G11: 12.5 | H11: 12 | I11: 25 | J11: 7.144 | K11: 35 | L11: 14000 | M11: 22000 | N11: 550 | O11: 145 | P11: 125 | Q11: 1250 | R11: 26 | S11: Cronidur 30 F1
A12: Schaeffler 61815-Y | B12: Thin DGBB (FST15 Inner) | C12: 75 | D12: 95 | E12: 10 | F12: 85 | G12: 13.7 | H12: 13.4 | I12: 0 | J12: 6 | K12: 26 | L12: 8500 | M12: 13000 | N12: 480 | O12: 7.1 | P12: 140 | Q12: 42 | R12: 1 | S12: FST15 Baseline
A13: FAG B71815-E-TPA-P4S-UL | B13: Thin ACBB (FST15 Stepped) | C13: 75 | D13: 95 | E13: 10 | F13: 85 | G13: 13.2 | H13: 14.8 | I13: 25 | J13: 7.144 | K13: 33 | L13: 10000 | M13: 16000 | N13: 430 | O13: 115 | P13: 135 | Q13: 360 | R13: 18 | S13: FST15 Stepped ACBB
A14: Schaeffler 61916 | B14: Medium Thin DGBB (ISO 19) | C14: 80 | D14: 110 | E14: 16 | F14: 95 | G14: 26.5 | H14: 24 | I14: 0 | J14: 10 | K14: 18 | L14: 6700 | M14: 8000 | N14: 620 | O14: 12 | P14: 380 | Q14: 75 | R14: 2 | S14: Rejected Packaging
A15: FAG B71916-E-TPA-P4S-UL | B15: Angular Contact (ISO 19) | C15: 80 | D15: 110 | E15: 16 | F15: 95 | G15: 33.5 | H15: 24 | I15: 25 | J15: 10 | K15: 21 | L15: 8500 | M15: 13000 | N15: 680 | O15: 185 | P15: 380 | Q15: 450 | R15: 20 | S15: Rejected Packaging
... A20: FAG QJ216-XL-MPA | B20: Four-Point Contact Ball | C20: 80 | D20: 140 | E20: 26 | F20: 110 | G20: 136 | H20: 137 | I20: 35 | J20: 18 | K20: 14 | L20: 3400 | M20: 5300 | N20: 1300 | O20: 350 | P20: 1700 | Q20: 260 | R20: 6 | S20: Rejected Split Ring

Sheet Bearing_Calculator
B1: FST 16 Wheel Bearing Sizing & Verification Calculator
B2: Formula Student Lisboa - Hub & Upright Wheel Assembly
B4: 1. BEARING SELECTION & CANDIDATE ARCHITECTURE
B5: Interface / Position | C5: Bearing Designation | D5: Series / Angle | E5: Reference Link
B6: Outer Bearing (Rim Side) | C6: Schaeffler 61816-Y | D6: =VLOOKUP(C6, Bearing_Database!A4:S20, 2, FALSE) | E6: ="Bore: " & VLOOKUP(C6, Bearing_Database!A4:S20, 3, FALSE) & " mm | Angle: " & VLOOKUP(C6, Bearing_Database!A4:S20, 9, FALSE) & " deg"
B7: Inner Bearing (Motor Side) | C7: Schaeffler 61816-Y | D7: =VLOOKUP(C7, Bearing_Database!A4:S20, 2, FALSE) | E7: ="Bore: " & VLOOKUP(C7, Bearing_Database!A4:S20, 3, FALSE) & " mm | Angle: " & VLOOKUP(C7, Bearing_Database!A4:S20, 9, FALSE) & " deg"
B9: 2. OPERATING CONDITIONS & VEHICLE DYNAMICS (PEAK CORNERING)
B10: Operating Parameter | C10: Value | D10: Unit | E10: Physical Engineering Note
B11: Tire Lateral Force (Fy) | C11: 4436.26 | D11: N | E11: Peak 1.8g steady-state cornering (LC3)
B12: Tire Vertical Wheel Load (Fz) | C12: 1787.31 | D12: N | E12: Vertical wheel load under weight transfer
B13: Loaded Tire Rolling Radius (Reff) | C13: 0.25 | D13: m | E13: Hoosier 18.0x6.0-10 under racing load
B14: Bearing Physical Center Span (Lb) | C14: 32 | D14: mm | E14: Center-to-center raceway distance
B15: Vehicle Track Speed (v) | C15: 100 | D15: km/h | E15: Operating cornering entry speed
B16: Track Operating Temperature (T) | C16: 80 | D16: deg C | E16: Equilibrium temperature under braking & motor
B17: Thread Pitch (M78x1.5) | C17: 1.5 | D17: mm | E17: Thread pitch for Preload Nut clamping
B19: 3. LOAD DISTRIBUTION & CONTACT MECHANICS
B20: Calculated Parameter | C20: Formula / Value | D20: Unit | E20: Engineering Verification
B21: Overturning Moment (Mx) | C21: =C11*C13 | D21: N*m | E21: Mx = Fy * Reff
B22: Outer Pressure Apex Distance (a_out) | C22: =IF(VLOOKUP(C6, Bearing_Database!A4:S20, 9, FALSE)>0, (VLOOKUP(C6, Bearing_Database!A4:S20, 6, FALSE)/2)*TAN(RADIANS(VLOOKUP(C6, Bearing_Database!A4:S20, 9, FALSE))), 0) | D22: mm | E22: a_out = (dm/2)*tan(alpha)
B23: Inner Pressure Apex Distance (a_in) | C23: =IF(VLOOKUP(C7, Bearing_Database!A4:S20, 9, FALSE)>0, (VLOOKUP(C7, Bearing_Database!A4:S20, 6, FALSE)/2)*TAN(RADIANS(VLOOKUP(C7, Bearing_Database!A4:S20, 9, FALSE))), 0) | D23: mm | E23: a_in = (dm/2)*tan(alpha)
B24: Effective Bearing Spread (H) | C24: =C14+C22+C23 | D24: mm | E24: H = Lb + a_out + a_in (O-arrangement spread)
B25: Decoupled Overturning Couple (F_couple) | C25: =C21/(C24/1000) | D25: N | E25: F_couple = Mx / H
B26: Peak Outer Radial Force (Fr_out) | C26: =C25+(C12/2) | D26: N | E26: Fr_out = F_couple + (Fz / 2)
B27: Peak Inner Radial Force (Fr_in) | C27: =ABS(-C25+(C12/2)) | D27: N | E27: Fr_in = |-F_couple + (Fz / 2)|
B28: Axial Thrust Force (Fa) | C28: =C11 | D28: N | E28: Fa = Fy (cornering thrust)
B30: 4. STATIC SAFETY FACTOR (ISO 76) & RATING LIFE (ISO 281)
B31: Life / Safety Parameter | C31: Outer Bearing | D31: Inner Bearing | E31: Unit | F31: Physical Engineering Formulation
B32: Equivalent Static Load (P0) | C32: =IF(VLOOKUP(C6, Bearing_Database!A4:S20, 9, FALSE)>0, MAX(C26, 0.5*C26+0.38*C28), MAX(C26, 0.6*C26+0.5*C28)) | D32: =IF(VLOOKUP(C7, Bearing_Database!A4:S20, 9, FALSE)>0, MAX(C27, 0.5*C27+0.38*C28), MAX(C27, 0.6*C27+0.5*C28)) | E32: N | F32: ISO 76 static equivalent load
B33: Static Safety Factor (S0 = C0r / P0) | C33: =(VLOOKUP(C6, Bearing_Database!A4:S20, 8, FALSE)*1000)/C32 | D33: =(VLOOKUP(C7, Bearing_Database!A4:S20, 8, FALSE)*1000)/D32 | E33: ratio | F33: Target S0 >= 1.5 (Green >= 1.5, Yellow 1.0-1.5, Red < 1.0)
B34: Wheel Rotational Speed (n_wheel) | C34: =((C15*1000/3600)/(2*PI()*C13))*60 | D34: =C34 | E34: rpm | F34: n = (v / (2 * pi * Reff)) * 60
B35: Dynamic Equivalent Spectrum Load (Peq) | C35: =(0.60*(1250^3) + 0.30*((0.55*C26)^3) + 0.08*(C26^3) + 0.02*(2600^3))^(1/3) | D35: =(0.60*(1250^3) + 0.30*((0.55*C27)^3) + 0.08*(C27^3) + 0.02*(2600^3))^(1/3) | E35: N | F35: ISO 281 cubic duty spectrum mean load
B36: Basic Rating Fatigue Life (L10h) | C36: =(10^6/(60*C34)) * ((VLOOKUP(C6, Bearing_Database!A4:S20, 7, FALSE)*1000)/C35)^3 | D36: =(10^6/(60*C34)) * ((VLOOKUP(C7, Bearing_Database!A4:S20, 7, FALSE)*1000)/D35)^3 | E36: Hours | F36: L10h = (10^6 / (60*n)) * (Cr / Peq)^3
B37: Equivalent Distance Life (L10km) | C37: =C36*C15 | D37: =D36*C15 | E37: km | F37: L10km = L10h * v (Full FS season ~ 500 km)
B39: 5. ELASTOKINEMATIC CAMBER STIFFNESS & ANGULAR COMPLIANCE
B40: Rigidity Parameter | C40: Value | D40: Unit | E40: Physical Engineering Note
B41: Angular Camber Stiffness (c_tilt) | C41: =0.5 * (VLOOKUP(C6, Bearing_Database!A4:S20, 14, FALSE)*1000000) * ((C24/1000)^2) * (PI()/180) | D41: N*m / deg | E41: c_tilt = 0.5 * Kr * H^2 (N*m/rad converted to N*m/deg)
B42: Angular Camber Deflection (gamma) | C42: =C21/C41 | D42: deg | E42: Elastokinematic hub deflection under peak cornering
B43: Tire Top Lateral Deflection | C43: =C13*RADIANS(C42)*1000 | D43: mm | E43: Reff * radians(gamma) * 1000 lateral displacement
B44: Rigidity Ratio vs Physical Span | C44: =(C24/C14)^2 | D44: ratio (x) | E44: Scaling factor (H / Lb)^2
B46: 6. PRELOAD MECHANICS & M78x1.5 PRELOAD NUT TORQUE
...
